<?xml version="1.0" encoding="utf-8"?>
<!-- This URDF was automatically created by SolidWorks to URDF Exporter! Originally created by Stephen Brawner (brawner@gmail.com) 
     Commit Version: 1.6.0-4-g7f85cfe  Build Version: 1.6.7995.38578
     For more information, please see http://wiki.ros.org/sw_urdf_exporter -->
<robot
  name="zwhand_17dof_left">
  <link
    name="base_link">
    <inertial>
      <origin
        xyz="-0.000665362536275292 0.000429152319376647 0.0585734122760588"
        rpy="0 0 0" />
      <mass
        value="0.0385843346295589" />
      <inertia
        ixx="4.77356774978713E-05"
        ixy="-1.33411467644044E-08"
        ixz="1.18868985582911E-07"
        iyy="3.16765609974547E-05"
        iyz="-6.12341578052794E-07"
        izz="1.95374414009174E-05" />
    </inertial>
    <visual>
      <origin
        xyz="0 0 0"
        rpy="0 0 0" />
      <geometry>
        <mesh
          filename="package://zwhand_17dof_left/meshes/base_link.STL" />
      </geometry>
      <material
        name="">
        <color
          rgba="1 1 1 1" />
      </material>
    </visual>
    <collision>
      <origin
        xyz="0 0 0"
        rpy="0 0 0" />
      <geometry>
        <mesh
          filename="package://zwhand_17dof_left/meshes/base_link.STL" />
      </geometry>
    </collision>
  </link>
  <link
    name="Link11">
    <inertial>
      <origin
        xyz="0.00439408811139754 -0.00911765065399595 0.00044871006172668"
        rpy="0 0 0" />
      <mass
        value="0.00138305741020588" />
      <inertia
        ixx="7.59113043365004E-08"
        ixy="2.30497822999331E-08"
        ixz="1.05687197853023E-10"
        iyy="5.246976242615E-08"
        iyz="1.35533885534063E-10"
        izz="1.16505696809913E-07" />
    </inertial>
    <visual>
      <origin
        xyz="0 0 0"
        rpy="0 0 0" />
      <geometry>
        <mesh
          filename="package://zwhand_17dof_left/meshes/Link11.STL" />
      </geometry>
      <material
        name="">
        <color
          rgba="1 1 1 1" />
      </material>
    </visual>
    <collision>
      <origin
        xyz="0 0 0"
        rpy="0 0 0" />
      <geometry>
        <mesh
          filename="package://zwhand_17dof_left/meshes/Link11.STL" />
      </geometry>
    </collision>
  </link>
  <joint
    name="Joint16"
    type="revolute">
    <origin
      xyz="0.0145000000000013 -0.019175845396938 0.032866829933102"
      rpy="-0.0872664625997253 0 0" />
    <parent
      link="base_link" />
    <child
      link="Link11" />
    <axis
      xyz="0 0 1" />
    <limit
      lower="0"
      upper="1.0472"
      effort="1"
      velocity="1" />
  </joint>
  <link
    name="Link12">
    <inertial>
      <origin
        xyz="-0.0193457288064523 -0.0970462057174385 0.00664758776330233"
        rpy="0 0 0" />
      <mass
        value="0.0984470630272566" />
      <inertia
        ixx="0.000585174590954754"
        ixy="-4.26494616303551E-06"
        ixz="1.17247059938109E-05"
        iyy="0.000248076456229318"
        iyz="-9.99315415835099E-06"
        izz="0.000805891897441605" />
    </inertial>
    <visual>
      <origin
        xyz="0 0 0"
        rpy="0 0 0" />
      <geometry>
        <mesh
          filename="package://zwhand_17dof_left/meshes/Link12.STL" />
      </geometry>
      <material
        name="">
        <color
          rgba="1 1 1 1" />
      </material>
    </visual>
    <collision>
      <origin
        xyz="0 0 0"
        rpy="0 0 0" />
      <geometry>
        <mesh
          filename="package://zwhand_17dof_left/meshes/Link12.STL" />
      </geometry>
    </collision>
  </link>
  <joint
    name="Joint3"
    type="revolute">
    <origin
      xyz="8.55267492552558E-05 -0.0225481366751174 0.00218716640100595"
      rpy="-1.5707963267949 0 -1.04719755119662" />
    <parent
      link="Link11" />
    <child
      link="Link12" />
    <axis
      xyz="0 0 -1" />
    <limit
      lower="0"
      upper="0.7854"
      effort="1"
      velocity="1" />
  </joint>
  <link
    name="Link13">
    <inertial>
      <origin
        xyz="0.011202607163177 -0.0161886608049256 -0.00825005840401396"
        rpy="0 0 0" />
      <mass
        value="0.00563386947432946" />
      <inertia
        ixx="6.49912296716302E-07"
        ixy="2.38322274804655E-07"
        ixz="-8.43114954825691E-13"
        iyy="6.9921432625115E-07"
        iyz="-3.81493429155989E-13"
        izz="8.14920242380477E-07" />
    </inertial>
    <visual>
      <origin
        xyz="0 0 0"
        rpy="0 0 0" />
      <geometry>
        <mesh
          filename="package://zwhand_17dof_left/meshes/Link13.STL" />
      </geometry>
      <material
        name="">
        <color
          rgba="1 1 1 1" />
      </material>
    </visual>
    <collision>
      <origin
        xyz="0 0 0"
        rpy="0 0 0" />
      <geometry>
        <mesh
          filename="package://zwhand_17dof_left/meshes/Link13.STL" />
      </geometry>
    </collision>
  </link>
  <joint
    name="Joint2"
    type="revolute">
    <origin
      xyz="0.0754452633218026 -0.0430611453900553 0.01845"
      rpy="0 0 0" />
    <parent
      link="Link12" />
    <child
      link="Link13" />
    <axis
      xyz="0 0 -1" />
    <limit
      lower="0"
      upper="1.2217"
      effort="1"
      velocity="1" />
  </joint>
  <link
    name="Link14">
    <inertial>
      <origin
        xyz="0.00912335650691751 -0.0132872172631343 -0.00819758291292656"
        rpy="0 0 0" />
      <mass
        value="0.00648852431372067" />
      <inertia
        ixx="4.01224481067621E-07"
        ixy="9.231707597789E-08"
        ixz="-4.70592158523467E-12"
        iyy="4.21613805872039E-07"
        iyz="-2.62778917769055E-12"
        izz="4.37154836305582E-07" />
    </inertial>
    <visual>
      <origin
        xyz="0 0 0"
        rpy="0 0 0" />
      <geometry>
        <mesh
          filename="package://zwhand_17dof_left/meshes/Link14.STL" />
      </geometry>
      <material
        name="">
        <color
          rgba="1 1 1 1" />
      </material>
    </visual>
    <collision>
      <origin
        xyz="0 0 0"
        rpy="0 0 0" />
      <geometry>
        <mesh
          filename="package://zwhand_17dof_left/meshes/Link14.STL" />
      </geometry>
    </collision>
  </link>
  <joint
    name="Joint1"
    type="revolute">
    <origin
      xyz="0.026080516434841 -0.0282252807189571 -5.23885481902089E-05"
      rpy="0 0 0" />
    <parent
      link="Link13" />
    <child
      link="Link14" />
    <axis
      xyz="0 0 -1" />
    <limit
      lower="0"
      upper="1.3963"
      effort="1"
      velocity="1" />
  </joint>
  <link
    name="Link21">
    <inertial>
      <origin
        xyz="-1.99944541305619E-08 3.46676293505599E-08 0.00478412417325754"
        rpy="0 0 0" />
      <mass
        value="0.000175293148492888" />
      <inertia
        ixx="3.20326613804737E-09"
        ixy="1.95339875476183E-15"
        ixz="-1.85926689618895E-15"
        iyy="2.99432681410188E-09"
        iyz="1.39840023510881E-15"
        izz="9.33097487974611E-10" />
    </inertial>
    <visual>
      <origin
        xyz="0 0 0"
        rpy="0 0 0" />
      <geometry>
        <mesh
          filename="package://zwhand_17dof_left/meshes/Link21.STL" />
      </geometry>
      <material
        name="">
        <color
          rgba="1 1 1 1" />
      </material>
    </visual>
    <collision>
      <origin
        xyz="0 0 0"
        rpy="0 0 0" />
      <geometry>
        <mesh
          filename="package://zwhand_17dof_left/meshes/Link21.STL" />
      </geometry>
    </collision>
  </link>
  <joint
    name="Joint17"
    type="revolute">
    <origin
      xyz="-0.003 -0.026 0.1465"
      rpy="-1.5708 0 -1.5708" />
    <parent
      link="base_link" />
    <child
      link="Link21" />
    <axis
      xyz="0 0 1" />
    <limit
      lower="0"
      upper="0.1745"
      effort="1"
      velocity="1" />
  </joint>
  <link
    name="Link22">
    <inertial>
      <origin
        xyz="-0.00159268176425252 0.0178802121706692 9.36361533254715E-06"
        rpy="0 0 0" />
      <mass
        value="0.00353149930058254" />
      <inertia
        ixx="5.02206916260674E-07"
        ixy="4.81072248366593E-08"
        ixz="8.72269899306731E-11"
        iyy="2.14660813704943E-07"
        iyz="2.05431535327336E-10"
        izz="5.11195737471112E-07" />
    </inertial>
    <visual>
      <origin
        xyz="0 0 0"
        rpy="0 0 0" />
      <geometry>
        <mesh
          filename="package://zwhand_17dof_left/meshes/Link22.STL" />
      </geometry>
      <material
        name="">
        <color
          rgba="1 1 1 1" />
      </material>
    </visual>
    <collision>
      <origin
        xyz="0 0 0"
        rpy="0 0 0" />
      <geometry>
        <mesh
          filename="package://zwhand_17dof_left/meshes/Link22.STL" />
      </geometry>
    </collision>
  </link>
  <joint
    name="Joint6"
    type="revolute">
    <origin
      xyz="0 0 0.0075729"
      rpy="3.1416 -1.5708 0" />
    <parent
      link="Link21" />
    <child
      link="Link22" />
    <axis
      xyz="0 0 -1" />
    <limit
      lower="0"
      upper="1.5708"
      effort="1"
      velocity="1" />
  </joint>
  <link
    name="Link23">
    <inertial>
      <origin
        xyz="0.00173129166368025 0.0194041831510843 -0.00701961228435177"
        rpy="0 0 0" />
      <mass
        value="0.0033267012363065" />
      <inertia
        ixx="5.01796570591849E-07"
        ixy="1.80444765827316E-08"
        ixz="-3.44143459501015E-10"
        iyy="1.81807323555466E-07"
        iyz="2.51342592421128E-09"
        izz="4.84095845487014E-07" />
    </inertial>
    <visual>
      <origin
        xyz="0 0 0"
        rpy="0 0 0" />
      <geometry>
        <mesh
          filename="package://zwhand_17dof_left/meshes/Link23.STL" />
      </geometry>
      <material
        name="">
        <color
          rgba="1 1 1 1" />
      </material>
    </visual>
    <collision>
      <origin
        xyz="0 0 0"
        rpy="0 0 0" />
      <geometry>
        <mesh
          filename="package://zwhand_17dof_left/meshes/Link23.STL" />
      </geometry>
    </collision>
  </link>
  <joint
    name="Joint5"
    type="revolute">
    <origin
      xyz="-0.00309877969012365 0.0355000017901757 0.00710000021640794"
      rpy="0 0 0" />
    <parent
      link="Link22" />
    <child
      link="Link23" />
    <axis
      xyz="0 0 -1" />
    <limit
      lower="0"
      upper="1.5708"
      effort="1"
      velocity="1" />
  </joint>
  <link
    name="Link24">
    <inertial>
      <origin
        xyz="0.00212399088950623 0.014358809540157 -0.00685032342087634"
        rpy="0 0 0" />
      <mass
        value="0.00435670454057234" />
      <inertia
        ixx="2.61711034670062E-07"
        ixy="6.86051419420172E-09"
        ixz="-7.34747393166894E-12"
        iyy="1.60348278042487E-07"
        iyz="-1.03333124450363E-11"
        izz="2.35997672269181E-07" />
    </inertial>
    <visual>
      <origin
        xyz="0 0 0"
        rpy="0 0 0" />
      <geometry>
        <mesh
          filename="package://zwhand_17dof_left/meshes/Link24.STL" />
      </geometry>
      <material
        name="">
        <color
          rgba="1 1 1 1" />
      </material>
    </visual>
    <collision>
      <origin
        xyz="0 0 0"
        rpy="0 0 0" />
      <geometry>
        <mesh
          filename="package://zwhand_17dof_left/meshes/Link24.STL" />
      </geometry>
    </collision>
  </link>
  <joint
    name="Joint4"
    type="revolute">
    <origin
      xyz="0.000531009916053093 0.0359999999999983 -0.000249999999993443"
      rpy="0 0 0" />
    <parent
      link="Link23" />
    <child
      link="Link24" />
    <axis
      xyz="0 0 -1" />
    <limit
      lower="0"
      upper="1.3963"
      effort="1"
      velocity="1" />
  </joint>
  <link
    name="Link31">
    <inertial>
      <origin
        xyz="-0.000869431576225304 0.0209895419638196 -0.00499248846806704"
        rpy="0 0 0" />
      <mass
        value="0.00412900648242841" />
      <inertia
        ixx="8.3373153381872E-07"
        ixy="2.58850827627914E-08"
        ixz="4.9831831930378E-11"
        iyy="2.52598947795254E-07"
        iyz="8.97414923978584E-11"
        izz="8.50957770179142E-07" />
    </inertial>
    <visual>
      <origin
        xyz="0 0 0"
        rpy="0 0 0" />
      <geometry>
        <mesh
          filename="package://zwhand_17dof_left/meshes/Link31.STL" />
      </geometry>
      <material
        name="">
        <color
          rgba="1 1 1 1" />
      </material>
    </visual>
    <collision>
      <origin
        xyz="0 0 0"
        rpy="0 0 0" />
      <geometry>
        <mesh
          filename="package://zwhand_17dof_left/meshes/Link31.STL" />
      </geometry>
    </collision>
  </link>
  <joint
    name="Joint9"
    type="revolute">
    <origin
      xyz="0.004 -0.011 0.1465"
      rpy="1.5708 0 0" />
    <parent
      link="base_link" />
    <child
      link="Link31" />
    <axis
      xyz="0 0 -1" />
    <limit
      lower="0"
      upper="1.5708"
      effort="1"
      velocity="1" />
  </joint>
  <link
    name="Link32">
    <inertial>
      <origin
        xyz="0.00173129166368043 0.0194041831510847 -0.00701961228435179"
        rpy="0 0 0" />
      <mass
        value="0.00332670123630653" />
      <inertia
        ixx="5.01796570591846E-07"
        ixy="1.80444765827371E-08"
        ixz="-3.44143459500954E-10"
        iyy="1.81807323555468E-07"
        iyz="2.51342592420707E-09"
        izz="4.84095845487013E-07" />
    </inertial>
    <visual>
      <origin
        xyz="0 0 0"
        rpy="0 0 0" />
      <geometry>
        <mesh
          filename="package://zwhand_17dof_left/meshes/Link32.STL" />
      </geometry>
      <material
        name="">
        <color
          rgba="1 1 1 1" />
      </material>
    </visual>
    <collision>
      <origin
        xyz="0 0 0"
        rpy="0 0 0" />
      <geometry>
        <mesh
          filename="package://zwhand_17dof_left/meshes/Link32.STL" />
      </geometry>
    </collision>
  </link>
  <joint
    name="Joint8"
    type="revolute">
    <origin
      xyz="-0.00245529051210972 0.0422499999999829 0.00210000000000033"
      rpy="0 0 0" />
    <parent
      link="Link31" />
    <child
      link="Link32" />
    <axis
      xyz="0 0 -1" />
    <limit
      lower="0"
      upper="1.5708"
      effort="1"
      velocity="1" />
  </joint>
  <link
    name="Link33">
    <inertial>
      <origin
        xyz="0.00212399088950624 0.0143588095401571 -0.00685032342087634"
        rpy="0 0 0" />
      <mass
        value="0.00435670454057236" />
      <inertia
        ixx="2.61711034670064E-07"
        ixy="6.86051419420156E-09"
        ixz="-7.3474739319345E-12"
        iyy="1.60348278042487E-07"
        iyz="-1.03333124452299E-11"
        izz="2.35997672269182E-07" />
    </inertial>
    <visual>
      <origin
        xyz="0 0 0"
        rpy="0 0 0" />
      <geometry>
        <mesh
          filename="package://zwhand_17dof_left/meshes/Link33.STL" />
      </geometry>
      <material
        name="">
        <color
          rgba="1 1 1 1" />
      </material>
    </visual>
    <collision>
      <origin
        xyz="0 0 0"
        rpy="0 0 0" />
      <geometry>
        <mesh
          filename="package://zwhand_17dof_left/meshes/Link33.STL" />
      </geometry>
    </collision>
  </link>
  <joint
    name="Joint7"
    type="revolute">
    <origin
      xyz="0.000531009916053095 0.0360000000000283 -0.000249999999992786"
      rpy="0 0 0" />
    <parent
      link="Link32" />
    <child
      link="Link33" />
    <axis
      xyz="0 0 -1" />
    <limit
      lower="0"
      upper="1.3963"
      effort="1"
      velocity="1" />
  </joint>
  <link
    name="Link41">
    <inertial>
      <origin
        xyz="-0.000869431576225269 0.0209895419638197 -0.00499248846806708"
        rpy="0 0 0" />
      <mass
        value="0.00412900648242839" />
      <inertia
        ixx="8.33731533818721E-07"
        ixy="2.58850827627923E-08"
        ixz="4.9831831930199E-11"
        iyy="2.52598947795253E-07"
        iyz="8.97414923988465E-11"
        izz="8.50957770179143E-07" />
    </inertial>
    <visual>
      <origin
        xyz="0 0 0"
        rpy="0 0 0" />
      <geometry>
        <mesh
          filename="package://zwhand_17dof_left/meshes/Link41.STL" />
      </geometry>
      <material
        name="">
        <color
          rgba="1 1 1 1" />
      </material>
    </visual>
    <collision>
      <origin
        xyz="0 0 0"
        rpy="0 0 0" />
      <geometry>
        <mesh
          filename="package://zwhand_17dof_left/meshes/Link41.STL" />
      </geometry>
    </collision>
  </link>
  <joint
    name="Joint12"
    type="revolute">
    <origin
      xyz="0.004 0.008 0.1415"
      rpy="1.5708 0 0" />
    <parent
      link="base_link" />
    <child
      link="Link41" />
    <axis
      xyz="0 0 -1" />
    <limit
      lower="0"
      upper="1.5708"
      effort="1"
      velocity="1" />
  </joint>
  <link
    name="Link42">
    <inertial>
      <origin
        xyz="0.00173129166368033 0.0194041831510845 -0.00701961228435175"
        rpy="0 0 0" />
      <mass
        value="0.00332670123630652" />
      <inertia
        ixx="5.01796570591847E-07"
        ixy="1.80444765827356E-08"
        ixz="-3.44143459501449E-10"
        iyy="1.81807323555467E-07"
        iyz="2.51342592420915E-09"
        izz="4.84095845487013E-07" />
    </inertial>
    <visual>
      <origin
        xyz="0 0 0"
        rpy="0 0 0" />
      <geometry>
        <mesh
          filename="package://zwhand_17dof_left/meshes/Link42.STL" />
      </geometry>
      <material
        name="">
        <color
          rgba="1 1 1 1" />
      </material>
    </visual>
    <collision>
      <origin
        xyz="0 0 0"
        rpy="0 0 0" />
      <geometry>
        <mesh
          filename="package://zwhand_17dof_left/meshes/Link42.STL" />
      </geometry>
    </collision>
  </link>
  <joint
    name="Joint11"
    type="revolute">
    <origin
      xyz="-0.00245529051210972 0.042249999999983 0.00210000000000033"
      rpy="0 0 0" />
    <parent
      link="Link41" />
    <child
      link="Link42" />
    <axis
      xyz="0 0 -1" />
    <limit
      lower="0"
      upper="1.3963"
      effort="1"
      velocity="1" />
  </joint>
  <link
    name="Link43">
    <inertial>
      <origin
        xyz="0.00212399088950624 0.0143588095401571 -0.00685032342087633"
        rpy="0 0 0" />
      <mass
        value="0.00435670454057232" />
      <inertia
        ixx="2.61711034670061E-07"
        ixy="6.86051419420196E-09"
        ixz="-7.34747393176319E-12"
        iyy="1.60348278042486E-07"
        iyz="-1.03333124450329E-11"
        izz="2.3599767226918E-07" />
    </inertial>
    <visual>
      <origin
        xyz="0 0 0"
        rpy="0 0 0" />
      <geometry>
        <mesh
          filename="package://zwhand_17dof_left/meshes/Link43.STL" />
      </geometry>
      <material
        name="">
        <color
          rgba="1 1 1 1" />
      </material>
    </visual>
    <collision>
      <origin
        xyz="0 0 0"
        rpy="0 0 0" />
      <geometry>
        <mesh
          filename="package://zwhand_17dof_left/meshes/Link43.STL" />
      </geometry>
    </collision>
  </link>
  <joint
    name="Joint10"
    type="revolute">
    <origin
      xyz="0.000531009916054976 0.0360000000000272 -0.000249999999992787"
      rpy="0 0 0" />
    <parent
      link="Link42" />
    <child
      link="Link43" />
    <axis
      xyz="0 0 -1" />
    <limit
      lower="0"
      upper="1.3963"
      effort="1"
      velocity="1" />
  </joint>
  <link
    name="Link51">
    <inertial>
      <origin
        xyz="-0.00116330985591655 0.018814841892457 -0.00499285693393129"
        rpy="0 0 0" />
      <mass
        value="0.00365895619048566" />
      <inertia
        ixx="5.89132787764106E-07"
        ixy="2.73655605674345E-08"
        ixz="4.41581503344011E-11"
        iyy="2.19961172347424E-07"
        iyz="8.09516563344114E-11"
        izz="6.02038239082363E-07" />
    </inertial>
    <visual>
      <origin
        xyz="0 0 0"
        rpy="0 0 0" />
      <geometry>
        <mesh
          filename="package://zwhand_17dof_left/meshes/Link51.STL" />
      </geometry>
      <material
        name="">
        <color
          rgba="1 1 1 1" />
      </material>
    </visual>
    <collision>
      <origin
        xyz="0 0 0"
        rpy="0 0 0" />
      <geometry>
        <mesh
          filename="package://zwhand_17dof_left/meshes/Link51.STL" />
      </geometry>
    </collision>
  </link>
  <joint
    name="Joint15"
    type="revolute">
    <origin
      xyz="0.00400000000000059 0.0269999999999997 0.1365"
      rpy="1.5707963267949 0 0" />
    <parent
      link="base_link" />
    <child
      link="Link51" />
    <axis
      xyz="0 0 -1" />
    <limit
      lower="0"
      upper="1.5708"
      effort="1"
      velocity="1" />
  </joint>
  <link
    name="Link52">
    <inertial>
      <origin
        xyz="0.00173129166368038 0.0194041831510846 -0.00701961228435175"
        rpy="0 0 0" />
      <mass
        value="0.00332670123630648" />
      <inertia
        ixx="5.01796570591838E-07"
        ixy="1.80444765827345E-08"
        ixz="-3.44143459501777E-10"
        iyy="1.81807323555466E-07"
        iyz="2.5134259242087E-09"
        izz="4.84095845487003E-07" />
    </inertial>
    <visual>
      <origin
        xyz="0 0 0"
        rpy="0 0 0" />
      <geometry>
        <mesh
          filename="package://zwhand_17dof_left/meshes/Link52.STL" />
      </geometry>
      <material
        name="">
        <color
          rgba="1 1 1 1" />
      </material>
    </visual>
    <collision>
      <origin
        xyz="0 0 0"
        rpy="0 0 0" />
      <geometry>
        <mesh
          filename="package://zwhand_17dof_left/meshes/Link52.STL" />
      </geometry>
    </collision>
  </link>
  <joint
    name="Joint14"
    type="revolute">
    <origin
      xyz="-0.00249695382373872 0.037249999999983 0.00210000000000033"
      rpy="0 0 0" />
    <parent
      link="Link51" />
    <child
      link="Link52" />
    <axis
      xyz="0 0 -1" />
    <limit
      lower="0"
      upper="1.5708"
      effort="1"
      velocity="1" />
  </joint>
  <link
    name="Link53">
    <inertial>
      <origin
        xyz="0.00212399088950624 0.0143588095401571 -0.00685032342087633"
        rpy="0 0 0" />
      <mass
        value="0.00435670454057234" />
      <inertia
        ixx="2.61711034670061E-07"
        ixy="6.86051419420143E-09"
        ixz="-7.3474739317253E-12"
        iyy="1.60348278042486E-07"
        iyz="-1.033331244591E-11"
        izz="2.3599767226918E-07" />
    </inertial>
    <visual>
      <origin
        xyz="0 0 0"
        rpy="0 0 0" />
      <geometry>
        <mesh
          filename="package://zwhand_17dof_left/meshes/Link53.STL" />
      </geometry>
      <material
        name="">
        <color
          rgba="1 1 1 1" />
      </material>
    </visual>
    <collision>
      <origin
        xyz="0 0 0"
        rpy="0 0 0" />
      <geometry>
        <mesh
          filename="package://zwhand_17dof_left/meshes/Link53.STL" />
      </geometry>
    </collision>
  </link>
  <joint
    name="Joint13"
    type="revolute">
    <origin
      xyz="0.000531009916049095 0.0360000000000283 -0.00024999999999278"
      rpy="0 0 0" />
    <parent
      link="Link52" />
    <child
      link="Link53" />
    <axis
      xyz="0 0 -1" />
    <limit
      lower="0"
      upper="1.3963"
      effort="1"
      velocity="1" />
  </joint>
</robot>