<?xml version="1.0" encoding="utf-8"?>
<!-- This URDF was automatically created by SolidWorks to URDF Exporter! Originally created by Stephen Brawner (brawner@gmail.com) 
     Commit Version: 1.6.0-4-g7f85cfe  Build Version: 1.6.7995.38578
     For more information, please see http://wiki.ros.org/sw_urdf_exporter -->
<robot
  name="zwhand_17dof_right">
  <link
    name="base_link">
    <inertial>
      <origin
        xyz="-0.00334751315498717 -9.87060418915648E-05 0.0728750696079386"
        rpy="0 0 0" />
      <mass
        value="0.0763799746467642" />
      <inertia
        ixx="0.000136808893519471"
        ixy="5.80849768228373E-08"
        ixz="8.69969846699736E-07"
        iyy="8.5772035596069E-05"
        iyz="-1.50211989767202E-06"
        izz="7.42577430311818E-05" />
    </inertial>
    <visual>
      <origin
        xyz="0 0 0"
        rpy="0 0 0" />
      <geometry>
        <mesh
          filename="package://zwhand_17dof_right/meshes/base_link.STL" />
      </geometry>
      <material
        name="">
        <color
          rgba="1 1 1 1" />
      </material>
    </visual>
    <collision>
      <origin
        xyz="0 0 0"
        rpy="0 0 0" />
      <geometry>
        <mesh
          filename="package://zwhand_17dof_right/meshes/base_link.STL" />
      </geometry>
    </collision>
  </link>
  <link
    name="Link11">
    <inertial>
      <origin
        xyz="0.00439409166664414 0.00911764355638027 0.000448720638245281"
        rpy="0 0 0" />
      <mass
        value="0.00138306011958178" />
      <inertia
        ixx="7.591177910473E-08"
        ixy="-2.30498293875914E-08"
        ixz="1.05599078653656E-10"
        iyy="5.24695211408071E-08"
        iyz="-1.35459434709014E-10"
        izz="1.1650585272924E-07" />
    </inertial>
    <visual>
      <origin
        xyz="0 0 0"
        rpy="0 0 0" />
      <geometry>
        <mesh
          filename="package://zwhand_17dof_right/meshes/Link11.STL" />
      </geometry>
      <material
        name="">
        <color
          rgba="1 1 1 1" />
      </material>
    </visual>
    <collision>
      <origin
        xyz="0 0 0"
        rpy="0 0 0" />
      <geometry>
        <mesh
          filename="package://zwhand_17dof_right/meshes/Link11.STL" />
      </geometry>
    </collision>
  </link>
  <joint
    name="Joint16"
    type="revolute">
    <origin
      xyz="0.0145000000000012 0.0191758453969375 0.0328668299330995"
      rpy="0.0872664625997253 0 0" />
    <parent
      link="base_link" />
    <child
      link="Link11" />
    <axis
      xyz="0 0 -1" />
    <limit
      lower="0"
      upper="1.0472"
      effort="1"
      velocity="1" />
  </joint>
  <link
    name="Link12">
    <inertial>
      <origin
        xyz="-0.0256445225392524 -0.0850697626962446 -0.00491773050030617"
        rpy="0 0 0" />
      <mass
        value="0.136241414927804" />
      <inertia
        ixx="0.000699846324507476"
        ixy="2.38934656324275E-05"
        ixz="-2.32164996056177E-05"
        iyy="0.000318301471062501"
        iyz="4.29961899739986E-06"
        izz="0.000951061019139629" />
    </inertial>
    <visual>
      <origin
        xyz="0 0 0"
        rpy="0 0 0" />
      <geometry>
        <mesh
          filename="package://zwhand_17dof_right/meshes/Link12.STL" />
      </geometry>
      <material
        name="">
        <color
          rgba="1 1 1 1" />
      </material>
    </visual>
    <collision>
      <origin
        xyz="0 0 0"
        rpy="0 0 0" />
      <geometry>
        <mesh
          filename="package://zwhand_17dof_right/meshes/Link12.STL" />
      </geometry>
    </collision>
  </link>
  <joint
    name="Joint3"
    type="revolute">
    <origin
      xyz="8.55267492552558E-05 0.0225481366751174 0.00218716640100842"
      rpy="-1.5707963267949 0 1.04719755119662" />
    <parent
      link="Link11" />
    <child
      link="Link12" />
    <axis
      xyz="0 0 -1" />
    <limit
      lower="0"
      upper="0.7854"
      effort="1"
      velocity="1" />
  </joint>
  <link
    name="Link13">
    <inertial>
      <origin
        xyz="0.0112026062086038 -0.0161887306855046 0.00825007658828168"
        rpy="0 0 0" />
      <mass
        value="0.0056338536086512" />
      <inertia
        ixx="6.49907544117079E-07"
        ixy="2.38320711503857E-07"
        ixz="-1.0523569483176E-12"
        iyy="6.99212260157111E-07"
        iyz="-2.50526292309768E-12"
        izz="8.1491843846749E-07" />
    </inertial>
    <visual>
      <origin
        xyz="0 0 0"
        rpy="0 0 0" />
      <geometry>
        <mesh
          filename="package://zwhand_17dof_right/meshes/Link13.STL" />
      </geometry>
      <material
        name="">
        <color
          rgba="1 1 1 1" />
      </material>
    </visual>
    <collision>
      <origin
        xyz="0 0 0"
        rpy="0 0 0" />
      <geometry>
        <mesh
          filename="package://zwhand_17dof_right/meshes/Link13.STL" />
      </geometry>
    </collision>
  </link>
  <joint
    name="Joint2"
    type="revolute">
    <origin
      xyz="0.0754452633218026 -0.0430611453900553 -0.01845"
      rpy="0 0 0" />
    <parent
      link="Link12" />
    <child
      link="Link13" />
    <axis
      xyz="0 0 -1" />
    <limit
      lower="0"
      upper="1.2217"
      effort="1"
      velocity="1" />
  </joint>
  <link
    name="Link14">
    <inertial>
      <origin
        xyz="0.00912321285541223 -0.013287503978651 0.00819738055268498"
        rpy="0 0 0" />
      <mass
        value="0.00648842636701499" />
      <inertia
        ixx="4.01213852016179E-07"
        ixy="9.23181511174076E-08"
        ixz="7.23041396033579E-12"
        iyy="4.21614363805887E-07"
        iyz="6.24897363279425E-12"
        izz="4.37132320375489E-07" />
    </inertial>
    <visual>
      <origin
        xyz="0 0 0"
        rpy="0 0 0" />
      <geometry>
        <mesh
          filename="package://zwhand_17dof_right/meshes/Link14.STL" />
      </geometry>
      <material
        name="">
        <color
          rgba="1 1 1 1" />
      </material>
    </visual>
    <collision>
      <origin
        xyz="0 0 0"
        rpy="0 0 0" />
      <geometry>
        <mesh
          filename="package://zwhand_17dof_right/meshes/Link14.STL" />
      </geometry>
    </collision>
  </link>
  <joint
    name="Joint1"
    type="revolute">
    <origin
      xyz="0.0260805164596955 -0.0282252790878162 5.23878148150966E-05"
      rpy="0 0 0" />
    <parent
      link="Link13" />
    <child
      link="Link14" />
    <axis
      xyz="0 0 -1" />
    <limit
      lower="0"
      upper="1.3963"
      effort="1"
      velocity="1" />
  </joint>
  <link
    name="Link21">
    <inertial>
      <origin
        xyz="-2.01623105294813E-08 5.55131685481269E-08 0.00478411936690889"
        rpy="0 0 0" />
      <mass
        value="0.000175293795964646" />
      <inertia
        ixx="3.20327721135577E-09"
        ixy="1.26388757063363E-15"
        ixz="-1.93517171416749E-15"
        iyy="2.99431954106679E-09"
        iyz="6.23069486982103E-15"
        izz="9.33099049110965E-10" />
    </inertial>
    <visual>
      <origin
        xyz="0 0 0"
        rpy="0 0 0" />
      <geometry>
        <mesh
          filename="package://zwhand_17dof_right/meshes/Link21.STL" />
      </geometry>
      <material
        name="">
        <color
          rgba="1 1 1 1" />
      </material>
    </visual>
    <collision>
      <origin
        xyz="0 0 0"
        rpy="0 0 0" />
      <geometry>
        <mesh
          filename="package://zwhand_17dof_right/meshes/Link21.STL" />
      </geometry>
    </collision>
  </link>
  <joint
    name="Joint17"
    type="revolute">
    <origin
      xyz="-0.003 0.026 0.1465"
      rpy="-1.5708 0 -1.5708" />
    <parent
      link="base_link" />
    <child
      link="Link21" />
    <axis
      xyz="0 0 -1" />
    <limit
      lower="0"
      upper="0.1745"
      effort="1"
      velocity="1" />
  </joint>
  <link
    name="Link22">
    <inertial>
      <origin
        xyz="-0.00159297362814294 0.0178803724392812 -9.3663529685227E-06"
        rpy="0 0 0" />
      <mass
        value="0.00353148699758135" />
      <inertia
        ixx="5.02224381060809E-07"
        ixy="4.81101293488808E-08"
        ixz="-9.35643263635852E-11"
        iyy="2.14662338246824E-07"
        iyz="-1.94484933556271E-10"
        izz="5.11201216651875E-07" />
    </inertial>
    <visual>
      <origin
        xyz="0 0 0"
        rpy="0 0 0" />
      <geometry>
        <mesh
          filename="package://zwhand_17dof_right/meshes/Link22.STL" />
      </geometry>
      <material
        name="">
        <color
          rgba="1 1 1 1" />
      </material>
    </visual>
    <collision>
      <origin
        xyz="0 0 0"
        rpy="0 0 0" />
      <geometry>
        <mesh
          filename="package://zwhand_17dof_right/meshes/Link22.STL" />
      </geometry>
    </collision>
  </link>
  <joint
    name="Joint6"
    type="revolute">
    <origin
      xyz="0 0 0.0075729"
      rpy="3.1416 -1.5708 0" />
    <parent
      link="Link21" />
    <child
      link="Link22" />
    <axis
      xyz="0 0 -1" />
    <limit
      lower="0"
      upper="1.5708"
      effort="1"
      velocity="1" />
  </joint>
  <link
    name="Link23">
    <inertial>
      <origin
        xyz="0.00173036742558064 0.0194038658984875 0.00702018473966805"
        rpy="0 0 0" />
      <mass
        value="0.00332671523871181" />
      <inertia
        ixx="5.0189723636832E-07"
        ixy="1.80450874860439E-08"
        ixz="3.22142927287787E-10"
        iyy="1.817878902822E-07"
        iyz="-2.52071388015267E-09"
        izz="4.84122152024226E-07" />
    </inertial>
    <visual>
      <origin
        xyz="0 0 0"
        rpy="0 0 0" />
      <geometry>
        <mesh
          filename="package://zwhand_17dof_right/meshes/Link23.STL" />
      </geometry>
      <material
        name="">
        <color
          rgba="1 1 1 1" />
      </material>
    </visual>
    <collision>
      <origin
        xyz="0 0 0"
        rpy="0 0 0" />
      <geometry>
        <mesh
          filename="package://zwhand_17dof_right/meshes/Link23.STL" />
      </geometry>
    </collision>
  </link>
  <joint
    name="Joint5"
    type="revolute">
    <origin
      xyz="-0.00309877968315736 0.0355000016355182 -0.00710000024679022"
      rpy="0 0 0" />
    <parent
      link="Link22" />
    <child
      link="Link23" />
    <axis
      xyz="0 0 -1" />
    <limit
      lower="0"
      upper="1.5708"
      effort="1"
      velocity="1" />
  </joint>
  <link
    name="Link24">
    <inertial>
      <origin
        xyz="0.00212344337927151 0.014357762146042 0.00685000145180472"
        rpy="0 0 0" />
      <mass
        value="0.004357252587498" />
      <inertia
        ixx="2.61726006310356E-07"
        ixy="6.84122199012498E-09"
        ixz="-2.28024729068479E-13"
        iyy="1.60359139736517E-07"
        iyz="-6.67144502136598E-12"
        izz="2.36034816409947E-07" />
    </inertial>
    <visual>
      <origin
        xyz="0 0 0"
        rpy="0 0 0" />
      <geometry>
        <mesh
          filename="package://zwhand_17dof_right/meshes/Link24.STL" />
      </geometry>
      <material
        name="">
        <color
          rgba="1 1 1 1" />
      </material>
    </visual>
    <collision>
      <origin
        xyz="0 0 0"
        rpy="0 0 0" />
      <geometry>
        <mesh
          filename="package://zwhand_17dof_right/meshes/Link24.STL" />
      </geometry>
    </collision>
  </link>
  <joint
    name="Joint4"
    type="revolute">
    <origin
      xyz="0.000531009916053093 0.0359999999999983 0.000249999999993443"
      rpy="0 0 0" />
    <parent
      link="Link23" />
    <child
      link="Link24" />
    <axis
      xyz="0 0 -1" />
    <limit
      lower="0"
      upper="1.3963"
      effort="1"
      velocity="1" />
  </joint>
  <link
    name="Link31">
    <inertial>
      <origin
        xyz="0.000868745319009459 0.02098942201628 -0.00599251522941843"
        rpy="0 0 0" />
      <mass
        value="0.00412923090315214" />
      <inertia
        ixx="8.33731915391634E-07"
        ixy="-2.58792982175749E-08"
        ixz="-5.90400930600074E-11"
        iyy="2.52636997460987E-07"
        iyz="5.97544264415539E-11"
        izz="8.50994323799685E-07" />
    </inertial>
    <visual>
      <origin
        xyz="0 0 0"
        rpy="0 0 0" />
      <geometry>
        <mesh
          filename="package://zwhand_17dof_right/meshes/Link31.STL" />
      </geometry>
      <material
        name="">
        <color
          rgba="1 1 1 1" />
      </material>
    </visual>
    <collision>
      <origin
        xyz="0 0 0"
        rpy="0 0 0" />
      <geometry>
        <mesh
          filename="package://zwhand_17dof_right/meshes/Link31.STL" />
      </geometry>
    </collision>
  </link>
  <joint
    name="Joint9"
    type="revolute">
    <origin
      xyz="0.004 0.012 0.1465"
      rpy="1.5708 0 3.1416" />
    <parent
      link="base_link" />
    <child
      link="Link31" />
    <axis
      xyz="0 0 1" />
    <limit
      lower="0"
      upper="1.5708"
      effort="1"
      velocity="1" />
  </joint>
  <link
    name="Link32">
    <inertial>
      <origin
        xyz="0.0017303674255806 0.0194038658984874 0.00702018473966808"
        rpy="0 0 0" />
      <mass
        value="0.00332671523871179" />
      <inertia
        ixx="5.01897236368311E-07"
        ixy="1.80450874860398E-08"
        ixz="3.22142927287661E-10"
        iyy="1.81787890282198E-07"
        iyz="-2.52071388015335E-09"
        izz="4.84122152024216E-07" />
    </inertial>
    <visual>
      <origin
        xyz="0 0 0"
        rpy="0 0 0" />
      <geometry>
        <mesh
          filename="package://zwhand_17dof_right/meshes/Link32.STL" />
      </geometry>
      <material
        name="">
        <color
          rgba="1 1 1 1" />
      </material>
    </visual>
    <collision>
      <origin
        xyz="0 0 0"
        rpy="0 0 0" />
      <geometry>
        <mesh
          filename="package://zwhand_17dof_right/meshes/Link32.STL" />
      </geometry>
    </collision>
  </link>
  <joint
    name="Joint8"
    type="revolute">
    <origin
      xyz="0.00245529051210972 0.0422499999999829 0.00110000000000033"
      rpy="3.14159265358979 0 3.14159265358979" />
    <parent
      link="Link31" />
    <child
      link="Link32" />
    <axis
      xyz="0 0 -1" />
    <limit
      lower="0"
      upper="1.5708"
      effort="1"
      velocity="1" />
  </joint>
  <link
    name="Link33">
    <inertial>
      <origin
        xyz="0.00212344337927153 0.0143577621460421 0.00685000145180461"
        rpy="0 0 0" />
      <mass
        value="0.00435725258749792" />
      <inertia
        ixx="2.61726006310346E-07"
        ixy="6.84122199012571E-09"
        ixz="-2.28024728052095E-13"
        iyy="1.60359139736516E-07"
        iyz="-6.67144502736485E-12"
        izz="2.36034816409936E-07" />
    </inertial>
    <visual>
      <origin
        xyz="0 0 0"
        rpy="0 0 0" />
      <geometry>
        <mesh
          filename="package://zwhand_17dof_right/meshes/Link33.STL" />
      </geometry>
      <material
        name="">
        <color
          rgba="1 1 1 1" />
      </material>
    </visual>
    <collision>
      <origin
        xyz="0 0 0"
        rpy="0 0 0" />
      <geometry>
        <mesh
          filename="package://zwhand_17dof_right/meshes/Link33.STL" />
      </geometry>
    </collision>
  </link>
  <joint
    name="Joint7"
    type="revolute">
    <origin
      xyz="0.000531009916053095 0.0360000000000283 0.000249999999992786"
      rpy="0 0 0" />
    <parent
      link="Link32" />
    <child
      link="Link33" />
    <axis
      xyz="0 0 -1" />
    <limit
      lower="0"
      upper="1.3963"
      effort="1"
      velocity="1" />
  </joint>
  <link
    name="Link41">
    <inertial>
      <origin
        xyz="-0.000868745319009373 -0.0209894220162799 -0.00599251522941843"
        rpy="0 0 0" />
      <mass
        value="0.00412923090315213" />
      <inertia
        ixx="8.33731915391625E-07"
        ixy="-2.58792982175735E-08"
        ixz="5.90400930598428E-11"
        iyy="2.52636997460987E-07"
        iyz="-5.97544264408575E-11"
        izz="8.50994323799675E-07" />
    </inertial>
    <visual>
      <origin
        xyz="0 0 0"
        rpy="0 0 0" />
      <geometry>
        <mesh
          filename="package://zwhand_17dof_right/meshes/Link41.STL" />
      </geometry>
      <material
        name="">
        <color
          rgba="1 1 1 1" />
      </material>
    </visual>
    <collision>
      <origin
        xyz="0 0 0"
        rpy="0 0 0" />
      <geometry>
        <mesh
          filename="package://zwhand_17dof_right/meshes/Link41.STL" />
      </geometry>
    </collision>
  </link>
  <joint
    name="Joint12"
    type="revolute">
    <origin
      xyz="0.004 -0.007 0.1415"
      rpy="-1.5708 0 0" />
    <parent
      link="base_link" />
    <child
      link="Link41" />
    <axis
      xyz="0 0 1" />
    <limit
      lower="0"
      upper="1.5708"
      effort="1"
      velocity="1" />
  </joint>
  <link
    name="Link42">
    <inertial>
      <origin
        xyz="0.00173036742558075 0.0194038658984877 0.00702018473966811"
        rpy="0 0 0" />
      <mass
        value="0.00332671523871179" />
      <inertia
        ixx="5.01897236368297E-07"
        ixy="1.80450874860446E-08"
        ixz="3.22142927287676E-10"
        iyy="1.81787890282199E-07"
        iyz="-2.52071388015208E-09"
        izz="4.84122152024203E-07" />
    </inertial>
    <visual>
      <origin
        xyz="0 0 0"
        rpy="0 0 0" />
      <geometry>
        <mesh
          filename="package://zwhand_17dof_right/meshes/Link42.STL" />
      </geometry>
      <material
        name="">
        <color
          rgba="1 1 1 1" />
      </material>
    </visual>
    <collision>
      <origin
        xyz="0 0 0"
        rpy="0 0 0" />
      <geometry>
        <mesh
          filename="package://zwhand_17dof_right/meshes/Link42.STL" />
      </geometry>
    </collision>
  </link>
  <joint
    name="Joint11"
    type="revolute">
    <origin
      xyz="-0.00245529051210972 -0.042249999999983 0.00110000000000034"
      rpy="3.14159265358979 0 0" />
    <parent
      link="Link41" />
    <child
      link="Link42" />
    <axis
      xyz="0 0 -1" />
    <limit
      lower="0"
      upper="1.3963"
      effort="1"
      velocity="1" />
  </joint>
  <link
    name="Link43">
    <inertial>
      <origin
        xyz="0.0021234433792715 0.014357762146042 0.00810000145181125"
        rpy="0 0 0" />
      <mass
        value="0.00435725258749801" />
      <inertia
        ixx="2.61726006310356E-07"
        ixy="6.84122199012535E-09"
        ixz="-2.28024728921931E-13"
        iyy="1.60359139736517E-07"
        iyz="-6.67144502170664E-12"
        izz="2.36034816409947E-07" />
    </inertial>
    <visual>
      <origin
        xyz="0 0 0"
        rpy="0 0 0" />
      <geometry>
        <mesh
          filename="package://zwhand_17dof_right/meshes/Link43.STL" />
      </geometry>
      <material
        name="">
        <color
          rgba="1 1 1 1" />
      </material>
    </visual>
    <collision>
      <origin
        xyz="0 0 0"
        rpy="0 0 0" />
      <geometry>
        <mesh
          filename="package://zwhand_17dof_right/meshes/Link43.STL" />
      </geometry>
    </collision>
  </link>
  <joint
    name="Joint10"
    type="revolute">
    <origin
      xyz="0.000531009916054976 0.0360000000000272 -0.00100000000001376"
      rpy="0 0 0" />
    <parent
      link="Link42" />
    <child
      link="Link43" />
    <axis
      xyz="0 0 -1" />
    <limit
      lower="0"
      upper="1.3963"
      effort="1"
      velocity="1" />
  </joint>
  <link
    name="Link51">
    <inertial>
      <origin
        xyz="-0.00116381680683495 -0.0188154039431175 -0.00599226085858628"
        rpy="0 0 0" />
      <mass
        value="0.00365896607296679" />
      <inertia
        ixx="5.89185920964713E-07"
        ixy="-2.73715947015778E-08"
        ixz="2.50960643195748E-11"
        iyy="2.19959685125764E-07"
        iyz="-8.60006928609268E-11"
        izz="6.02016975139215E-07" />
    </inertial>
    <visual>
      <origin
        xyz="0 0 0"
        rpy="0 0 0" />
      <geometry>
        <mesh
          filename="package://zwhand_17dof_right/meshes/Link51.STL" />
      </geometry>
      <material
        name="">
        <color
          rgba="1 1 1 1" />
      </material>
    </visual>
    <collision>
      <origin
        xyz="0 0 0"
        rpy="0 0 0" />
      <geometry>
        <mesh
          filename="package://zwhand_17dof_right/meshes/Link51.STL" />
      </geometry>
    </collision>
  </link>
  <joint
    name="Joint15"
    type="revolute">
    <origin
      xyz="0.00400000000000048 -0.0260000000000003 0.1365"
      rpy="-1.5707963267949 0 0" />
    <parent
      link="base_link" />
    <child
      link="Link51" />
    <axis
      xyz="0 0 1" />
    <limit
      lower="0"
      upper="1.5708"
      effort="1"
      velocity="1" />
  </joint>
  <link
    name="Link52">
    <inertial>
      <origin
        xyz="0.00173036742558073 0.0194038658984877 0.00702018473966805"
        rpy="0 0 0" />
      <mass
        value="0.00332671523871181" />
      <inertia
        ixx="5.01897236368306E-07"
        ixy="1.80450874860468E-08"
        ixz="3.22142927288437E-10"
        iyy="1.81787890282201E-07"
        iyz="-2.52071388015354E-09"
        izz="4.84122152024212E-07" />
    </inertial>
    <visual>
      <origin
        xyz="0 0 0"
        rpy="0 0 0" />
      <geometry>
        <mesh
          filename="package://zwhand_17dof_right/meshes/Link52.STL" />
      </geometry>
      <material
        name="">
        <color
          rgba="1 1 1 1" />
      </material>
    </visual>
    <collision>
      <origin
        xyz="0 0 0"
        rpy="0 0 0" />
      <geometry>
        <mesh
          filename="package://zwhand_17dof_right/meshes/Link52.STL" />
      </geometry>
    </collision>
  </link>
  <joint
    name="Joint14"
    type="revolute">
    <origin
      xyz="-0.00249695382373872 -0.037249999999983 0.00110000000000034"
      rpy="3.14159265358979 0 0" />
    <parent
      link="Link51" />
    <child
      link="Link52" />
    <axis
      xyz="0 0 -1" />
    <limit
      lower="0"
      upper="1.5708"
      effort="1"
      velocity="1" />
  </joint>
  <link
    name="Link53">
    <inertial>
      <origin
        xyz="0.00212344337927152 0.014357762146042 0.0068500014518047"
        rpy="0 0 0" />
      <mass
        value="0.00435725258749798" />
      <inertia
        ixx="2.61726006310355E-07"
        ixy="6.84122199012561E-09"
        ixz="-2.28024729055511E-13"
        iyy="1.60359139736516E-07"
        iyz="-6.67144502171971E-12"
        izz="2.36034816409946E-07" />
    </inertial>
    <visual>
      <origin
        xyz="0 0 0"
        rpy="0 0 0" />
      <geometry>
        <mesh
          filename="package://zwhand_17dof_right/meshes/Link53.STL" />
      </geometry>
      <material
        name="">
        <color
          rgba="1 1 1 1" />
      </material>
    </visual>
    <collision>
      <origin
        xyz="0 0 0"
        rpy="0 0 0" />
      <geometry>
        <mesh
          filename="package://zwhand_17dof_right/meshes/Link53.STL" />
      </geometry>
    </collision>
  </link>
  <joint
    name="Joint13"
    type="revolute">
    <origin
      xyz="0.000531009916049095 0.0360000000000283 0.00024999999999278"
      rpy="0 0 0" />
    <parent
      link="Link52" />
    <child
      link="Link53" />
    <axis
      xyz="0 0 -1" />
    <limit
      lower="0"
      upper="1.3963"
      effort="1"
      velocity="1" />
  </joint>
</robot>